время события:2023-04-11 15:46:59,778 - уровень:ERROR - сообщение:Internal Server Error: / - путь:C:\Users\misha\PycharmProjects\NIS-Portal\venv\lib\site-packages\django\utils\log.py: стэк ошибки:(<class 'django.db.utils.OperationalError'>, OperationalError('no such table: django_session'), <traceback object at 0x000001A56BA86440>)
Traceback (most recent call last):
  File "C:\Users\misha\PycharmProjects\NIS-Portal\venv\lib\site-packages\django\contrib\sessions\backends\base.py", line 187, in _get_session
    return self._session_cache
AttributeError: 'SessionStore' object has no attribute '_session_cache'

During handling of the above exception, another exception occurred:

Traceback (most recent call last):
  File "C:\Users\misha\PycharmProjects\NIS-Portal\venv\lib\site-packages\django\db\backends\utils.py", line 89, in _execute
    return self.cursor.execute(sql, params)
  File "C:\Users\misha\PycharmProjects\NIS-Portal\venv\lib\site-packages\django\db\backends\sqlite3\base.py", line 357, in execute
    return Database.Cursor.execute(self, query, params)
sqlite3.OperationalError: no such table: django_session

The above exception was the direct cause of the following exception:

Traceback (most recent call last):
  File "C:\Users\misha\PycharmProjects\NIS-Portal\venv\lib\site-packages\django\core\handlers\exception.py", line 55, in inner
    response = get_response(request)
  File "C:\Users\misha\Desktop\Python\SkillFactory\NIS-Portal\NIS-Portal\infoPortal\news\middlewares.py", line 10, in __call__
    tzname = request.session.get('django_timezone')  # пытаемся забрать часовой пояс из сессии
  File "C:\Users\misha\PycharmProjects\NIS-Portal\venv\lib\site-packages\django\contrib\sessions\backends\base.py", line 68, in get
    return self._session.get(key, default)
  File "C:\Users\misha\PycharmProjects\NIS-Portal\venv\lib\site-packages\django\contrib\sessions\backends\base.py", line 192, in _get_session
    self._session_cache = self.load()
  File "C:\Users\misha\PycharmProjects\NIS-Portal\venv\lib\site-packages\django\contrib\sessions\backends\db.py", line 42, in load
    s = self._get_session_from_db()
  File "C:\Users\misha\PycharmProjects\NIS-Portal\venv\lib\site-packages\django\contrib\sessions\backends\db.py", line 32, in _get_session_from_db
    return self.model.objects.get(
  File "C:\Users\misha\PycharmProjects\NIS-Portal\venv\lib\site-packages\django\db\models\manager.py", line 85, in manager_method
    return getattr(self.get_queryset(), name)(*args, **kwargs)
  File "C:\Users\misha\PycharmProjects\NIS-Portal\venv\lib\site-packages\django\db\models\query.py", line 646, in get
    num = len(clone)
  File "C:\Users\misha\PycharmProjects\NIS-Portal\venv\lib\site-packages\django\db\models\query.py", line 376, in __len__
    self._fetch_all()
  File "C:\Users\misha\PycharmProjects\NIS-Portal\venv\lib\site-packages\django\db\models\query.py", line 1867, in _fetch_all
    self._result_cache = list(self._iterable_class(self))
  File "C:\Users\misha\PycharmProjects\NIS-Portal\venv\lib\site-packages\django\db\models\query.py", line 87, in __iter__
    results = compiler.execute_sql(
  File "C:\Users\misha\PycharmProjects\NIS-Portal\venv\lib\site-packages\django\db\models\sql\compiler.py", line 1398, in execute_sql
    cursor.execute(sql, params)
  File "C:\Users\misha\PycharmProjects\NIS-Portal\venv\lib\site-packages\django\db\backends\utils.py", line 103, in execute
    return super().execute(sql, params)
  File "C:\Users\misha\PycharmProjects\NIS-Portal\venv\lib\site-packages\django\db\backends\utils.py", line 67, in execute
    return self._execute_with_wrappers(
  File "C:\Users\misha\PycharmProjects\NIS-Portal\venv\lib\site-packages\django\db\backends\utils.py", line 80, in _execute_with_wrappers
    return executor(sql, params, many, context)
  File "C:\Users\misha\PycharmProjects\NIS-Portal\venv\lib\site-packages\django\db\backends\utils.py", line 89, in _execute
    return self.cursor.execute(sql, params)
  File "C:\Users\misha\PycharmProjects\NIS-Portal\venv\lib\site-packages\django\db\utils.py", line 91, in __exit__
    raise dj_exc_value.with_traceback(traceback) from exc_value
  File "C:\Users\misha\PycharmProjects\NIS-Portal\venv\lib\site-packages\django\db\backends\utils.py", line 89, in _execute
    return self.cursor.execute(sql, params)
  File "C:\Users\misha\PycharmProjects\NIS-Portal\venv\lib\site-packages\django\db\backends\sqlite3\base.py", line 357, in execute
    return Database.Cursor.execute(self, query, params)
django.db.utils.OperationalError: no such table: django_session
время события:2023-04-11 15:46:59,783 - уровень:ERROR - сообщение:"GET / HTTP/1.1" 500 156511 - путь:C:\Users\misha\PycharmProjects\NIS-Portal\venv\lib\site-packages\django\core\servers\basehttp.py: стэк ошибки:None
время события:2023-04-11 15:47:14,824 - уровень:ERROR - сообщение:Internal Server Error: /admin/ - путь:C:\Users\misha\PycharmProjects\NIS-Portal\venv\lib\site-packages\django\utils\log.py: стэк ошибки:(<class 'django.db.utils.OperationalError'>, OperationalError('no such table: django_session'), <traceback object at 0x000001A56BA99C40>)
Traceback (most recent call last):
  File "C:\Users\misha\PycharmProjects\NIS-Portal\venv\lib\site-packages\django\contrib\sessions\backends\base.py", line 187, in _get_session
    return self._session_cache
AttributeError: 'SessionStore' object has no attribute '_session_cache'

During handling of the above exception, another exception occurred:

Traceback (most recent call last):
  File "C:\Users\misha\PycharmProjects\NIS-Portal\venv\lib\site-packages\django\db\backends\utils.py", line 89, in _execute
    return self.cursor.execute(sql, params)
  File "C:\Users\misha\PycharmProjects\NIS-Portal\venv\lib\site-packages\django\db\backends\sqlite3\base.py", line 357, in execute
    return Database.Cursor.execute(self, query, params)
sqlite3.OperationalError: no such table: django_session

The above exception was the direct cause of the following exception:

Traceback (most recent call last):
  File "C:\Users\misha\PycharmProjects\NIS-Portal\venv\lib\site-packages\django\core\handlers\exception.py", line 55, in inner
    response = get_response(request)
  File "C:\Users\misha\Desktop\Python\SkillFactory\NIS-Portal\NIS-Portal\infoPortal\news\middlewares.py", line 10, in __call__
    tzname = request.session.get('django_timezone')  # пытаемся забрать часовой пояс из сессии
  File "C:\Users\misha\PycharmProjects\NIS-Portal\venv\lib\site-packages\django\contrib\sessions\backends\base.py", line 68, in get
    return self._session.get(key, default)
  File "C:\Users\misha\PycharmProjects\NIS-Portal\venv\lib\site-packages\django\contrib\sessions\backends\base.py", line 192, in _get_session
    self._session_cache = self.load()
  File "C:\Users\misha\PycharmProjects\NIS-Portal\venv\lib\site-packages\django\contrib\sessions\backends\db.py", line 42, in load
    s = self._get_session_from_db()
  File "C:\Users\misha\PycharmProjects\NIS-Portal\venv\lib\site-packages\django\contrib\sessions\backends\db.py", line 32, in _get_session_from_db
    return self.model.objects.get(
  File "C:\Users\misha\PycharmProjects\NIS-Portal\venv\lib\site-packages\django\db\models\manager.py", line 85, in manager_method
    return getattr(self.get_queryset(), name)(*args, **kwargs)
  File "C:\Users\misha\PycharmProjects\NIS-Portal\venv\lib\site-packages\django\db\models\query.py", line 646, in get
    num = len(clone)
  File "C:\Users\misha\PycharmProjects\NIS-Portal\venv\lib\site-packages\django\db\models\query.py", line 376, in __len__
    self._fetch_all()
  File "C:\Users\misha\PycharmProjects\NIS-Portal\venv\lib\site-packages\django\db\models\query.py", line 1867, in _fetch_all
    self._result_cache = list(self._iterable_class(self))
  File "C:\Users\misha\PycharmProjects\NIS-Portal\venv\lib\site-packages\django\db\models\query.py", line 87, in __iter__
    results = compiler.execute_sql(
  File "C:\Users\misha\PycharmProjects\NIS-Portal\venv\lib\site-packages\django\db\models\sql\compiler.py", line 1398, in execute_sql
    cursor.execute(sql, params)
  File "C:\Users\misha\PycharmProjects\NIS-Portal\venv\lib\site-packages\django\db\backends\utils.py", line 103, in execute
    return super().execute(sql, params)
  File "C:\Users\misha\PycharmProjects\NIS-Portal\venv\lib\site-packages\django\db\backends\utils.py", line 67, in execute
    return self._execute_with_wrappers(
  File "C:\Users\misha\PycharmProjects\NIS-Portal\venv\lib\site-packages\django\db\backends\utils.py", line 80, in _execute_with_wrappers
    return executor(sql, params, many, context)
  File "C:\Users\misha\PycharmProjects\NIS-Portal\venv\lib\site-packages\django\db\backends\utils.py", line 89, in _execute
    return self.cursor.execute(sql, params)
  File "C:\Users\misha\PycharmProjects\NIS-Portal\venv\lib\site-packages\django\db\utils.py", line 91, in __exit__
    raise dj_exc_value.with_traceback(traceback) from exc_value
  File "C:\Users\misha\PycharmProjects\NIS-Portal\venv\lib\site-packages\django\db\backends\utils.py", line 89, in _execute
    return self.cursor.execute(sql, params)
  File "C:\Users\misha\PycharmProjects\NIS-Portal\venv\lib\site-packages\django\db\backends\sqlite3\base.py", line 357, in execute
    return Database.Cursor.execute(self, query, params)
django.db.utils.OperationalError: no such table: django_session
время события:2023-04-11 15:47:14,829 - уровень:ERROR - сообщение:"GET /admin/ HTTP/1.1" 500 156663 - путь:C:\Users\misha\PycharmProjects\NIS-Portal\venv\lib\site-packages\django\core\servers\basehttp.py: стэк ошибки:None
время события:2023-04-11 15:51:45,168 - уровень:ERROR - сообщение:Internal Server Error: /users/upgrade/ - путь:C:\Users\misha\PycharmProjects\NIS-Portal\venv\lib\site-packages\django\utils\log.py: стэк ошибки:(<class 'django.contrib.auth.models.Group.DoesNotExist'>, DoesNotExist('Group matching query does not exist.'), <traceback object at 0x000002BE1E005E00>)
Traceback (most recent call last):
  File "C:\Users\misha\PycharmProjects\NIS-Portal\venv\lib\site-packages\django\core\handlers\exception.py", line 55, in inner
    response = get_response(request)
  File "C:\Users\misha\PycharmProjects\NIS-Portal\venv\lib\site-packages\django\core\handlers\base.py", line 197, in _get_response
    response = wrapped_callback(request, *callback_args, **callback_kwargs)
  File "C:\Users\misha\PycharmProjects\NIS-Portal\venv\lib\site-packages\django\contrib\auth\decorators.py", line 23, in _wrapped_view
    return view_func(request, *args, **kwargs)
  File "C:\Users\misha\Desktop\Python\SkillFactory\NIS-Portal\NIS-Portal\infoPortal\users\views.py", line 29, in upgrade_me
    authors_group = Group.objects.get(name='authors')
  File "C:\Users\misha\PycharmProjects\NIS-Portal\venv\lib\site-packages\django\db\models\manager.py", line 85, in manager_method
    return getattr(self.get_queryset(), name)(*args, **kwargs)
  File "C:\Users\misha\PycharmProjects\NIS-Portal\venv\lib\site-packages\django\db\models\query.py", line 650, in get
    raise self.model.DoesNotExist(
django.contrib.auth.models.Group.DoesNotExist: Group matching query does not exist.
время события:2023-04-11 15:51:45,172 - уровень:ERROR - сообщение:"GET /users/upgrade/ HTTP/1.1" 500 86465 - путь:C:\Users\misha\PycharmProjects\NIS-Portal\venv\lib\site-packages\django\core\servers\basehttp.py: стэк ошибки:None
время события:2023-05-25 13:28:54,154 - уровень:ERROR - сообщение:"GET / HTTP/1.1" 500 59 - путь:C:\Users\misha\PycharmProjects\NIS-Portal\venv\lib\site-packages\django\core\servers\basehttp.py: стэк ошибки:None
